2025-10-20 17:26:38 - main - ERROR - Error: 2025-10-20 17:26:06 - data_preparation - INFO - ============================================================
2025-10-20 17:26:06 - data_preparation - INFO - DATA PREPARATION
2025-10-20 17:26:06 - data_preparation - INFO - ============================================================
2025-10-20 17:26:37 - data_preparation - ERROR - 
\u2717 Data preparation failed: [Errno 2] No such file or directory: 'data/raw\\inflation.csv'
--- Logging error ---
Traceback (most recent call last):
  File "C:\Users\tchok\Desktop\projects\optimal_monetary_policy_with_rl\venv\Lib\site-packages\urllib3\connectionpool.py", line 534, in _make_request
    response = conn.getresponse()
               ^^^^^^^^^^^^^^^^^^
  File "C:\Users\tchok\Desktop\projects\optimal_monetary_policy_with_rl\venv\Lib\site-packages\urllib3\connection.py", line 565, in getresponse
    httplib_response = super().getresponse()
                       ^^^^^^^^^^^^^^^^^^^^^
  File "C:\Users\tchok\Desktop\projects\optimal_monetary_policy_with_rl\venv\Lib\http\client.py", line 1430, in getresponse
    response.begin()
  File "C:\Users\tchok\Desktop\projects\optimal_monetary_policy_with_rl\venv\Lib\http\client.py", line 331, in begin
    version, status, reason = self._read_status()
                              ^^^^^^^^^^^^^^^^^^^
  File "C:\Users\tchok\Desktop\projects\optimal_monetary_policy_with_rl\venv\Lib\http\client.py", line 292, in _read_status
    line = str(self.fp.readline(_MAXLINE + 1), "iso-8859-1")
               ^^^^^^^^^^^^^^^^^^^^^^^^^^^^^^
  File "C:\Users\tchok\Desktop\projects\optimal_monetary_policy_with_rl\venv\Lib\socket.py", line 720, in readinto
    return self._sock.recv_into(b)
           ^^^^^^^^^^^^^^^^^^^^^^^
  File "C:\Users\tchok\Desktop\projects\optimal_monetary_policy_with_rl\venv\Lib\ssl.py", line 1251, in recv_into
    return self.read(nbytes, buffer)
           ^^^^^^^^^^^^^^^^^^^^^^^^^
  File "C:\Users\tchok\Desktop\projects\optimal_monetary_policy_with_rl\venv\Lib\ssl.py", line 1103, in read
    return self._sslobj.read(len, buffer)
           ^^^^^^^^^^^^^^^^^^^^^^^^^^^^^^
TimeoutError: The read operation timed out

The above exception was the direct cause of the following exception:

Traceback (most recent call last):
  File "C:\Users\tchok\Desktop\projects\optimal_monetary_policy_with_rl\venv\Lib\site-packages\requests\adapters.py", line 644, in send
    resp = conn.urlopen(
           ^^^^^^^^^^^^^
  File "C:\Users\tchok\Desktop\projects\optimal_monetary_policy_with_rl\venv\Lib\site-packages\urllib3\connectionpool.py", line 841, in urlopen
    retries = retries.increment(
              ^^^^^^^^^^^^^^^^^^
  File "C:\Users\tchok\Desktop\projects\optimal_monetary_policy_with_rl\venv\Lib\site-packages\urllib3\util\retry.py", line 474, in increment
    raise reraise(type(error), error, _stacktrace)
          ^^^^^^^^^^^^^^^^^^^^^^^^^^^^^^^^^^^^^^^^
  File "C:\Users\tchok\Desktop\projects\optimal_monetary_policy_with_rl\venv\Lib\site-packages\urllib3\util\util.py", line 39, in reraise
    raise value
  File "C:\Users\tchok\Desktop\projects\optimal_monetary_policy_with_rl\venv\Lib\site-packages\urllib3\connectionpool.py", line 787, in urlopen
    response = self._make_request(
               ^^^^^^^^^^^^^^^^^^^
  File "C:\Users\tchok\Desktop\projects\optimal_monetary_policy_with_rl\venv\Lib\site-packages\urllib3\connectionpool.py", line 536, in _make_request
    self._raise_timeout(err=e, url=url, timeout_value=read_timeout)
  File "C:\Users\tchok\Desktop\projects\optimal_monetary_policy_with_rl\venv\Lib\site-packages\urllib3\connectionpool.py", line 367, in _raise_timeout
    raise ReadTimeoutError(
urllib3.exceptions.ReadTimeoutError: HTTPSConnectionPool(host='fred.stlouisfed.org', port=443): Read timed out. (read timeout=30)

During handling of the above exception, another exception occurred:

Traceback (most recent call last):
  File "C:\Users\tchok\Desktop\projects\optimal_monetary_policy_with_rl\src\data\data_loader.py", line 47, in load_us_data
    gdp_deflator = pdr.get_data_fred('GDPDEF', start=start_date, end=end_date)
                   ^^^^^^^^^^^^^^^^^^^^^^^^^^^^^^^^^^^^^^^^^^^^^^^^^^^^^^^^^^^
  File "C:\Users\tchok\Desktop\projects\optimal_monetary_policy_with_rl\venv\Lib\site-packages\pandas_datareader\data.py", line 72, in get_data_fred
    return FredReader(*args, **kwargs).read()
           ^^^^^^^^^^^^^^^^^^^^^^^^^^^^^^^^^^
  File "C:\Users\tchok\Desktop\projects\optimal_monetary_policy_with_rl\venv\Lib\site-packages\pandas_datareader\fred.py", line 27, in read
    return self._read()
           ^^^^^^^^^^^^
  File "C:\Users\tchok\Desktop\projects\optimal_monetary_policy_with_rl\venv\Lib\site-packages\pandas_datareader\fred.py", line 62, in _read
    [fetch_data(url, n) for url, n in zip(urls, names)], axis=1, join="outer"
     ^^^^^^^^^^^^^^^^^^
  File "C:\Users\tchok\Desktop\projects\optimal_monetary_policy_with_rl\venv\Lib\site-packages\pandas_datareader\fred.py", line 41, in fetch_data
    resp = self._read_url_as_StringIO(url)
           ^^^^^^^^^^^^^^^^^^^^^^^^^^^^^^^
  File "C:\Users\tchok\Desktop\projects\optimal_monetary_policy_with_rl\venv\Lib\site-packages\pandas_datareader\base.py", line 119, in _read_url_as_StringIO
    response = self._get_response(url, params=params)
               ^^^^^^^^^^^^^^^^^^^^^^^^^^^^^^^^^^^^^^
  File "C:\Users\tchok\Desktop\projects\optimal_monetary_policy_with_rl\venv\Lib\site-packages\pandas_datareader\base.py", line 155, in _get_response
    response = self.session.get(
               ^^^^^^^^^^^^^^^^^
  File "C:\Users\tchok\Desktop\projects\optimal_monetary_policy_with_rl\venv\Lib\site-packages\requests\sessions.py", line 602, in get
    return self.request("GET", url, **kwargs)
           ^^^^^^^^^^^^^^^^^^^^^^^^^^^^^^^^^^
  File "C:\Users\tchok\Desktop\projects\optimal_monetary_policy_with_rl\venv\Lib\site-packages\requests\sessions.py", line 589, in request
    resp = self.send(prep, **send_kwargs)
           ^^^^^^^^^^^^^^^^^^^^^^^^^^^^^^
  File "C:\Users\tchok\Desktop\projects\optimal_monetary_policy_with_rl\venv\Lib\site-packages\requests\sessions.py", line 703, in send
    r = adapter.send(request, **kwargs)
        ^^^^^^^^^^^^^^^^^^^^^^^^^^^^^^^
  File "C:\Users\tchok\Desktop\projects\optimal_monetary_policy_with_rl\venv\Lib\site-packages\requests\adapters.py", line 690, in send
    raise ReadTimeout(e, request=request)
requests.exceptions.ReadTimeout: HTTPSConnectionPool(host='fred.stlouisfed.org', port=443): Read timed out. (read timeout=30)

During handling of the above exception, another exception occurred:

Traceback (most recent call last):
  File "C:\Users\tchok\Desktop\projects\optimal_monetary_policy_with_rl\scripts\data_preparation.py", line 28, in main
    data_loader = DataLoader(
                  ^^^^^^^^^^^
  File "C:\Users\tchok\Desktop\projects\optimal_monetary_policy_with_rl\src\data\data_loader.py", line 235, in __init__
    self.df = load_us_data(start_date, end_date, data_dir)
              ^^^^^^^^^^^^^^^^^^^^^^^^^^^^^^^^^^^^^^^^^^^^
  File "C:\Users\tchok\Desktop\projects\optimal_monetary_policy_with_rl\src\data\data_loader.py", line 95, in load_us_data
    inflation = pd.read_csv(inflation_path, index_col=0, parse_dates=True)
                ^^^^^^^^^^^^^^^^^^^^^^^^^^^^^^^^^^^^^^^^^^^^^^^^^^^^^^^^^^
  File "C:\Users\tchok\Desktop\projects\optimal_monetary_policy_with_rl\venv\Lib\site-packages\pandas\io\parsers\readers.py", line 1026, in read_csv
    return _read(filepath_or_buffer, kwds)
           ^^^^^^^^^^^^^^^^^^^^^^^^^^^^^^^
  File "C:\Users\tchok\Desktop\projects\optimal_monetary_policy_with_rl\venv\Lib\site-packages\pandas\io\parsers\readers.py", line 620, in _read
    parser = TextFileReader(filepath_or_buffer, **kwds)
             ^^^^^^^^^^^^^^^^^^^^^^^^^^^^^^^^^^^^^^^^^^
  File "C:\Users\tchok\Desktop\projects\optimal_monetary_policy_with_rl\venv\Lib\site-packages\pandas\io\parsers\readers.py", line 1620, in __init__
    self._engine = self._make_engine(f, self.engine)
                   ^^^^^^^^^^^^^^^^^^^^^^^^^^^^^^^^^
  File "C:\Users\tchok\Desktop\projects\optimal_monetary_policy_with_rl\venv\Lib\site-packages\pandas\io\parsers\readers.py", line 1880, in _make_engine
    self.handles = get_handle(
                   ^^^^^^^^^^^
  File "C:\Users\tchok\Desktop\projects\optimal_monetary_policy_with_rl\venv\Lib\site-packages\pandas\io\common.py", line 873, in get_handle
    handle = open(
             ^^^^^
FileNotFoundError: [Errno 2] No such file or directory: 'data/raw\\inflation.csv'

During handling of the above exception, another exception occurred:

Traceback (most recent call last):
  File "C:\Users\tchok\Desktop\projects\optimal_monetary_policy_with_rl\venv\Lib\logging\__init__.py", line 1163, in emit
    stream.write(msg + self.terminator)
  File "C:\Users\tchok\Desktop\projects\optimal_monetary_policy_with_rl\venv\Lib\encodings\cp1252.py", line 19, in encode
    return codecs.charmap_encode(input,self.errors,encoding_table)[0]
           ^^^^^^^^^^^^^^^^^^^^^^^^^^^^^^^^^^^^^^^^^^^^^^^^^^^^^^^
UnicodeEncodeError: 'charmap' codec can't encode character '\u2717' in position 51: character maps to <undefined>
Call stack:
  File "C:\Users\tchok\Desktop\projects\optimal_monetary_policy_with_rl\scripts\data_preparation.py", line 48, in <module>
    sys.exit(main())
  File "C:\Users\tchok\Desktop\projects\optimal_monetary_policy_with_rl\scripts\data_preparation.py", line 43, in main
    logger.error(f"\n\u2717 Data preparation failed: {str(e)}")
Message: "\n\u2717 Data preparation failed: [Errno 2] No such file or directory: 'data/raw\\\\inflation.csv'"
Arguments: ()

2025-10-20 17:28:56 - main - ERROR - Error: 2025-10-20 17:28:25 - data_preparation - INFO - ============================================================
2025-10-20 17:28:25 - data_preparation - INFO - DATA PREPARATION
2025-10-20 17:28:25 - data_preparation - INFO - ============================================================
2025-10-20 17:28:56 - data_preparation - ERROR - 
\u2717 Data preparation failed: [Errno 2] No such file or directory: 'data/raw\\inflation.csv'
--- Logging error ---
Traceback (most recent call last):
  File "C:\Users\tchok\Desktop\projects\optimal_monetary_policy_with_rl\venv\Lib\site-packages\urllib3\connectionpool.py", line 534, in _make_request
    response = conn.getresponse()
               ^^^^^^^^^^^^^^^^^^
  File "C:\Users\tchok\Desktop\projects\optimal_monetary_policy_with_rl\venv\Lib\site-packages\urllib3\connection.py", line 565, in getresponse
    httplib_response = super().getresponse()
                       ^^^^^^^^^^^^^^^^^^^^^
  File "C:\Users\tchok\Desktop\projects\optimal_monetary_policy_with_rl\venv\Lib\http\client.py", line 1430, in getresponse
    response.begin()
  File "C:\Users\tchok\Desktop\projects\optimal_monetary_policy_with_rl\venv\Lib\http\client.py", line 331, in begin
    version, status, reason = self._read_status()
                              ^^^^^^^^^^^^^^^^^^^
  File "C:\Users\tchok\Desktop\projects\optimal_monetary_policy_with_rl\venv\Lib\http\client.py", line 292, in _read_status
    line = str(self.fp.readline(_MAXLINE + 1), "iso-8859-1")
               ^^^^^^^^^^^^^^^^^^^^^^^^^^^^^^
  File "C:\Users\tchok\Desktop\projects\optimal_monetary_policy_with_rl\venv\Lib\socket.py", line 720, in readinto
    return self._sock.recv_into(b)
           ^^^^^^^^^^^^^^^^^^^^^^^
  File "C:\Users\tchok\Desktop\projects\optimal_monetary_policy_with_rl\venv\Lib\ssl.py", line 1251, in recv_into
    return self.read(nbytes, buffer)
           ^^^^^^^^^^^^^^^^^^^^^^^^^
  File "C:\Users\tchok\Desktop\projects\optimal_monetary_policy_with_rl\venv\Lib\ssl.py", line 1103, in read
    return self._sslobj.read(len, buffer)
           ^^^^^^^^^^^^^^^^^^^^^^^^^^^^^^
TimeoutError: The read operation timed out

The above exception was the direct cause of the following exception:

Traceback (most recent call last):
  File "C:\Users\tchok\Desktop\projects\optimal_monetary_policy_with_rl\venv\Lib\site-packages\requests\adapters.py", line 644, in send
    resp = conn.urlopen(
           ^^^^^^^^^^^^^
  File "C:\Users\tchok\Desktop\projects\optimal_monetary_policy_with_rl\venv\Lib\site-packages\urllib3\connectionpool.py", line 841, in urlopen
    retries = retries.increment(
              ^^^^^^^^^^^^^^^^^^
  File "C:\Users\tchok\Desktop\projects\optimal_monetary_policy_with_rl\venv\Lib\site-packages\urllib3\util\retry.py", line 474, in increment
    raise reraise(type(error), error, _stacktrace)
          ^^^^^^^^^^^^^^^^^^^^^^^^^^^^^^^^^^^^^^^^
  File "C:\Users\tchok\Desktop\projects\optimal_monetary_policy_with_rl\venv\Lib\site-packages\urllib3\util\util.py", line 39, in reraise
    raise value
  File "C:\Users\tchok\Desktop\projects\optimal_monetary_policy_with_rl\venv\Lib\site-packages\urllib3\connectionpool.py", line 787, in urlopen
    response = self._make_request(
               ^^^^^^^^^^^^^^^^^^^
  File "C:\Users\tchok\Desktop\projects\optimal_monetary_policy_with_rl\venv\Lib\site-packages\urllib3\connectionpool.py", line 536, in _make_request
    self._raise_timeout(err=e, url=url, timeout_value=read_timeout)
  File "C:\Users\tchok\Desktop\projects\optimal_monetary_policy_with_rl\venv\Lib\site-packages\urllib3\connectionpool.py", line 367, in _raise_timeout
    raise ReadTimeoutError(
urllib3.exceptions.ReadTimeoutError: HTTPSConnectionPool(host='fred.stlouisfed.org', port=443): Read timed out. (read timeout=30)

During handling of the above exception, another exception occurred:

Traceback (most recent call last):
  File "C:\Users\tchok\Desktop\projects\optimal_monetary_policy_with_rl\src\data\data_loader.py", line 47, in load_us_data
    gdp_deflator = pdr.get_data_fred('GDPDEF', start=start_date, end=end_date)
                   ^^^^^^^^^^^^^^^^^^^^^^^^^^^^^^^^^^^^^^^^^^^^^^^^^^^^^^^^^^^
  File "C:\Users\tchok\Desktop\projects\optimal_monetary_policy_with_rl\venv\Lib\site-packages\pandas_datareader\data.py", line 72, in get_data_fred
    return FredReader(*args, **kwargs).read()
           ^^^^^^^^^^^^^^^^^^^^^^^^^^^^^^^^^^
  File "C:\Users\tchok\Desktop\projects\optimal_monetary_policy_with_rl\venv\Lib\site-packages\pandas_datareader\fred.py", line 27, in read
    return self._read()
           ^^^^^^^^^^^^
  File "C:\Users\tchok\Desktop\projects\optimal_monetary_policy_with_rl\venv\Lib\site-packages\pandas_datareader\fred.py", line 62, in _read
    [fetch_data(url, n) for url, n in zip(urls, names)], axis=1, join="outer"
     ^^^^^^^^^^^^^^^^^^
  File "C:\Users\tchok\Desktop\projects\optimal_monetary_policy_with_rl\venv\Lib\site-packages\pandas_datareader\fred.py", line 41, in fetch_data
    resp = self._read_url_as_StringIO(url)
           ^^^^^^^^^^^^^^^^^^^^^^^^^^^^^^^
  File "C:\Users\tchok\Desktop\projects\optimal_monetary_policy_with_rl\venv\Lib\site-packages\pandas_datareader\base.py", line 119, in _read_url_as_StringIO
    response = self._get_response(url, params=params)
               ^^^^^^^^^^^^^^^^^^^^^^^^^^^^^^^^^^^^^^
  File "C:\Users\tchok\Desktop\projects\optimal_monetary_policy_with_rl\venv\Lib\site-packages\pandas_datareader\base.py", line 155, in _get_response
    response = self.session.get(
               ^^^^^^^^^^^^^^^^^
  File "C:\Users\tchok\Desktop\projects\optimal_monetary_policy_with_rl\venv\Lib\site-packages\requests\sessions.py", line 602, in get
    return self.request("GET", url, **kwargs)
           ^^^^^^^^^^^^^^^^^^^^^^^^^^^^^^^^^^
  File "C:\Users\tchok\Desktop\projects\optimal_monetary_policy_with_rl\venv\Lib\site-packages\requests\sessions.py", line 589, in request
    resp = self.send(prep, **send_kwargs)
           ^^^^^^^^^^^^^^^^^^^^^^^^^^^^^^
  File "C:\Users\tchok\Desktop\projects\optimal_monetary_policy_with_rl\venv\Lib\site-packages\requests\sessions.py", line 703, in send
    r = adapter.send(request, **kwargs)
        ^^^^^^^^^^^^^^^^^^^^^^^^^^^^^^^
  File "C:\Users\tchok\Desktop\projects\optimal_monetary_policy_with_rl\venv\Lib\site-packages\requests\adapters.py", line 690, in send
    raise ReadTimeout(e, request=request)
requests.exceptions.ReadTimeout: HTTPSConnectionPool(host='fred.stlouisfed.org', port=443): Read timed out. (read timeout=30)

During handling of the above exception, another exception occurred:

Traceback (most recent call last):
  File "C:\Users\tchok\Desktop\projects\optimal_monetary_policy_with_rl\scripts\data_preparation.py", line 28, in main
    data_loader = DataLoader(
                  ^^^^^^^^^^^
  File "C:\Users\tchok\Desktop\projects\optimal_monetary_policy_with_rl\src\data\data_loader.py", line 235, in __init__
    self.df = load_us_data(start_date, end_date, data_dir)
              ^^^^^^^^^^^^^^^^^^^^^^^^^^^^^^^^^^^^^^^^^^^^
  File "C:\Users\tchok\Desktop\projects\optimal_monetary_policy_with_rl\src\data\data_loader.py", line 95, in load_us_data
    inflation = pd.read_csv(inflation_path, index_col=0, parse_dates=True)
                ^^^^^^^^^^^^^^^^^^^^^^^^^^^^^^^^^^^^^^^^^^^^^^^^^^^^^^^^^^
  File "C:\Users\tchok\Desktop\projects\optimal_monetary_policy_with_rl\venv\Lib\site-packages\pandas\io\parsers\readers.py", line 1026, in read_csv
    return _read(filepath_or_buffer, kwds)
           ^^^^^^^^^^^^^^^^^^^^^^^^^^^^^^^
  File "C:\Users\tchok\Desktop\projects\optimal_monetary_policy_with_rl\venv\Lib\site-packages\pandas\io\parsers\readers.py", line 620, in _read
    parser = TextFileReader(filepath_or_buffer, **kwds)
             ^^^^^^^^^^^^^^^^^^^^^^^^^^^^^^^^^^^^^^^^^^
  File "C:\Users\tchok\Desktop\projects\optimal_monetary_policy_with_rl\venv\Lib\site-packages\pandas\io\parsers\readers.py", line 1620, in __init__
    self._engine = self._make_engine(f, self.engine)
                   ^^^^^^^^^^^^^^^^^^^^^^^^^^^^^^^^^
  File "C:\Users\tchok\Desktop\projects\optimal_monetary_policy_with_rl\venv\Lib\site-packages\pandas\io\parsers\readers.py", line 1880, in _make_engine
    self.handles = get_handle(
                   ^^^^^^^^^^^
  File "C:\Users\tchok\Desktop\projects\optimal_monetary_policy_with_rl\venv\Lib\site-packages\pandas\io\common.py", line 873, in get_handle
    handle = open(
             ^^^^^
FileNotFoundError: [Errno 2] No such file or directory: 'data/raw\\inflation.csv'

During handling of the above exception, another exception occurred:

Traceback (most recent call last):
  File "C:\Users\tchok\Desktop\projects\optimal_monetary_policy_with_rl\venv\Lib\logging\__init__.py", line 1163, in emit
    stream.write(msg + self.terminator)
  File "C:\Users\tchok\Desktop\projects\optimal_monetary_policy_with_rl\venv\Lib\encodings\cp1252.py", line 19, in encode
    return codecs.charmap_encode(input,self.errors,encoding_table)[0]
           ^^^^^^^^^^^^^^^^^^^^^^^^^^^^^^^^^^^^^^^^^^^^^^^^^^^^^^^
UnicodeEncodeError: 'charmap' codec can't encode character '\u2717' in position 51: character maps to <undefined>
Call stack:
  File "C:\Users\tchok\Desktop\projects\optimal_monetary_policy_with_rl\scripts\data_preparation.py", line 48, in <module>
    sys.exit(main())
  File "C:\Users\tchok\Desktop\projects\optimal_monetary_policy_with_rl\scripts\data_preparation.py", line 43, in main
    logger.error(f"\n\u2717 Data preparation failed: {str(e)}")
Message: "\n\u2717 Data preparation failed: [Errno 2] No such file or directory: 'data/raw\\\\inflation.csv'"
Arguments: ()

